{
  "uid" : "54f006ebb885816b",
  "name" : "Handle non-existent identities",
  "fullName" : "Manage digital identities via TPC_Web: Handle non-existent identities",
  "historyId" : "764ce2de7c30e452606468e2d948243f",
  "time" : {
    "start" : 1746616898724,
    "stop" : 1746616899300,
    "duration" : 576
  },
  "status" : "broken",
  "statusMessage" : "TypeError: step_attempt_view_nonexistent() got an unexpected keyword argument 'non_existent_ID'\n",
  "statusTrace" : "  File \"/home/runner/work/trustpoint/trustpoint/.venv/lib/python3.12/site-packages/behave/model.py\", line 1909, in run\n    match.run(runner.context)\n  File \"/home/runner/work/trustpoint/trustpoint/.venv/lib/python3.12/site-packages/behave/matchers.py\", line 104, in run\n    self.func(context, *args, **kwargs)\n",
  "flaky" : false,
  "newFailed" : false,
  "beforeStages" : [ ],
  "testStage" : {
    "status" : "broken",
    "statusMessage" : "TypeError: step_attempt_view_nonexistent() got an unexpected keyword argument 'non_existent_ID'\n",
    "statusTrace" : "  File \"/home/runner/work/trustpoint/trustpoint/.venv/lib/python3.12/site-packages/behave/model.py\", line 1909, in run\n    match.run(runner.context)\n  File \"/home/runner/work/trustpoint/trustpoint/.venv/lib/python3.12/site-packages/behave/matchers.py\", line 104, in run\n    self.func(context, *args, **kwargs)\n",
    "steps" : [ {
      "name" : "Given the admin user is logged into TPC_Web",
      "time" : {
        "start" : 1746616898726,
        "stop" : 1746616899271,
        "duration" : 545
      },
      "status" : "passed",
      "steps" : [ ],
      "attachments" : [ ],
      "parameters" : [ ],
      "stepsCount" : 0,
      "attachmentsCount" : 0,
      "shouldDisplayMessage" : false,
      "hasContent" : false
    }, {
      "name" : "When the admin attempts to view the details of a non-existent identity \"NonExistentID\"",
      "time" : {
        "start" : 1746616899271,
        "stop" : 1746616899272,
        "duration" : 1
      },
      "status" : "broken",
      "statusMessage" : "TypeError: step_attempt_view_nonexistent() got an unexpected keyword argument 'non_existent_ID'\n",
      "statusTrace" : "  File \"/home/runner/work/trustpoint/trustpoint/.venv/lib/python3.12/site-packages/behave/model.py\", line 1909, in run\n    match.run(runner.context)\n  File \"/home/runner/work/trustpoint/trustpoint/.venv/lib/python3.12/site-packages/behave/matchers.py\", line 104, in run\n    self.func(context, *args, **kwargs)\n",
      "steps" : [ ],
      "attachments" : [ ],
      "parameters" : [ ],
      "stepsCount" : 0,
      "attachmentsCount" : 0,
      "shouldDisplayMessage" : true,
      "hasContent" : true
    }, {
      "name" : "Then the system should display an error message stating \"Identity not found\"",
      "time" : {
        "start" : 1746616899299,
        "stop" : 1746616899300,
        "duration" : 1
      },
      "status" : "skipped",
      "steps" : [ ],
      "attachments" : [ ],
      "parameters" : [ ],
      "stepsCount" : 0,
      "attachmentsCount" : 0,
      "shouldDisplayMessage" : false,
      "hasContent" : false
    } ],
    "attachments" : [ ],
    "parameters" : [ ],
    "stepsCount" : 3,
    "attachmentsCount" : 0,
    "shouldDisplayMessage" : false,
    "hasContent" : true
  },
  "afterStages" : [ ],
  "labels" : [ {
    "name" : "severity",
    "value" : "normal"
  }, {
    "name" : "feature",
    "value" : "Manage digital identities via TPC_Web"
  }, {
    "name" : "framework",
    "value" : "behave"
  }, {
    "name" : "language",
    "value" : "cpython3"
  }, {
    "name" : "resultFormat",
    "value" : "allure2"
  } ],
  "parameters" : [ ],
  "links" : [ ],
  "hidden" : false,
  "retry" : false,
  "extra" : {
    "severity" : "normal",
    "retries" : [ ],
    "categories" : [ {
      "name" : "Test defects",
      "matchedStatuses" : [ ],
      "flaky" : false
    } ],
    "tags" : [ ]
  },
  "source" : "54f006ebb885816b.json",
  "parameterValues" : [ ]
}